<sdf version='1.7'>
  <model name='origins'>
    <link name='base_link'>
      <inertial>
        <pose>0 0 0 0 -0 0</pose>
        <mass>140</mass>
        <inertia>
          <ixx>5</ixx>
          <ixy>0</ixy>
          <ixz>0</ixz>
          <iyy>5</iyy>
          <iyz>0</iyz>
          <izz>5</izz>
        </inertia>
      </inertial>
      <collision name='base_link_collision'>
        <pose>0 0 0 0 -0 0</pose>
        <geometry>
          <box>
            <size>0.2 0.3 0.1</size>
          </box>
        </geometry>
      </collision>
      <collision name='base_link_fixed_joint_lump__wheel_1_collision_1'>
        <pose>0 0 0 0 -0 0</pose>
        <geometry>
          <cylinder>
            <length>0.05</length>
            <radius>0.05</radius>
          </cylinder>
        </geometry>
      </collision>
      <collision name='base_link_fixed_joint_lump__wheel_2_collision_2'>
        <pose>0 0 0 0 -0 0</pose>
        <geometry>
          <cylinder>
            <length>0.05</length>
            <radius>0.05</radius>
          </cylinder>
        </geometry>
      </collision>
      <collision name='base_link_fixed_joint_lump__wheel_3_collision_3'>
        <pose>0 0 0 0 -0 0</pose>
        <geometry>
          <cylinder>
            <length>0.05</length>
            <radius>0.05</radius>
          </cylinder>
        </geometry>
      </collision>
      <collision name='base_link_fixed_joint_lump__wheel_4_collision_4'>
        <pose>0 0 0 0 -0 0</pose>
        <geometry>
          <cylinder>
            <length>0.05</length>
            <radius>0.05</radius>
          </cylinder>
        </geometry>
      </collision>
      <visual name='base_link_visual'>
        <pose>0 0 0.05 0 -0 0</pose>
        <geometry>
          <box>
            <size>0.2 0.3 0.1</size>
          </box>
        </geometry>
      </visual>
      <visual name='base_link_fixed_joint_lump__wheel_1_visual_1'>
        <pose>0.1 0.1 0 0 1.5 0</pose>
        <geometry>
          <cylinder>
            <length>0.05</length>
            <radius>0.05</radius>
          </cylinder>
        </geometry>
      </visual>
      <visual name='base_link_fixed_joint_lump__wheel_2_visual_2'>
        <pose>-0.1 0.1 0 0 1.5 0</pose>
        <geometry>
          <cylinder>
            <length>0.05</length>
            <radius>0.05</radius>
          </cylinder>
        </geometry>
      </visual>
      <visual name='base_link_fixed_joint_lump__wheel_3_visual_3'>
        <pose>0.1 -0.1 0 0 1.5 0</pose>
        <geometry>
          <cylinder>
            <length>0.05</length>
            <radius>0.05</radius>
          </cylinder>
        </geometry>
      </visual>
      <visual name='base_link_fixed_joint_lump__wheel_4_visual_4'>
        <pose>-0.1 -0.1 0 0 1.5 0</pose>
        <geometry>
          <cylinder>
            <length>0.05</length>
            <radius>0.05</radius>
          </cylinder>
        </geometry>
      </visual>
    </link>
    <joint name='base_to_arm_base' type='revolute'>
      <pose relative_to='base_link'>0 0 0 0 -0 0</pose>
      <parent>base_link</parent>
      <child>arm_base</child>
      <axis>
        <xyz>0 0 1</xyz>
        <limit>
          <lower>-1e+16</lower>
          <upper>1e+16</upper>
        </limit>
        <dynamics>
          <spring_reference>0</spring_reference>
          <spring_stiffness>0</spring_stiffness>
        </dynamics>
      </axis>
    </joint>
    <link name='arm_base'>
      <pose relative_to='base_to_arm_base'>0 0 0 0 -0 0</pose>
      <inertial>
        <pose>0 0 0 0 -0 0</pose>
        <mass>1</mass>
        <inertia>
          <ixx>1</ixx>
          <ixy>0</ixy>
          <ixz>0</ixz>
          <iyy>1</iyy>
          <iyz>0</iyz>
          <izz>1</izz>
        </inertia>
      </inertial>
      <collision name='arm_base_collision'>
        <pose>0 0 0 0 -0 0</pose>
        <geometry>
          <box>
            <size>0.1 0.1 0.1</size>
          </box>
        </geometry>
      </collision>
      <visual name='arm_base_visual'>
        <pose>0 0 0.1 0 -0 0</pose>
        <geometry>
          <box>
            <size>0.1 0.1 0.1</size>
          </box>
        </geometry>
      </visual>
    </link>
    <joint name='arm_1_to_arm_base' type='revolute'>
      <pose relative_to='arm_base'>0 0 0.15 0 -0 0</pose>
      <parent>arm_base</parent>
      <child>arm_1</child>
      <axis>
        <xyz>1 0 0</xyz>
        <limit>
          <lower>-1</lower>
          <upper>1</upper>
          <effort>1000</effort>
          <velocity>0.5</velocity>
        </limit>
        <dynamics>
          <spring_reference>0</spring_reference>
          <spring_stiffness>0</spring_stiffness>
        </dynamics>
      </axis>
    </joint>
    <link name='arm_1'>
      <pose relative_to='arm_1_to_arm_base'>0 0 0 0 -0 0</pose>
      <inertial>
        <pose>0 0 0 0 -0 0</pose>
        <mass>1</mass>
        <inertia>
          <ixx>1</ixx>
          <ixy>0</ixy>
          <ixz>0</ixz>
          <iyy>1</iyy>
          <iyz>0</iyz>
          <izz>1</izz>
        </inertia>
      </inertial>
      <collision name='arm_1_collision'>
        <pose>0 0 0 0 -0 0</pose>
        <geometry>
          <box>
            <size>0.05 0.05 0.5</size>
          </box>
        </geometry>
      </collision>
      <visual name='arm_1_visual'>
        <pose>0 0 0.25 0 -0 0</pose>
        <geometry>
          <box>
            <size>0.05 0.05 0.5</size>
          </box>
        </geometry>
      </visual>
    </link>
    <joint name='arm_2_to_arm_1' type='revolute'>
      <pose relative_to='arm_1'>0 0 0.45 0 -0 0</pose>
      <parent>arm_1</parent>
      <child>arm_2</child>
      <axis>
        <xyz>1 0 0</xyz>
        <limit>
          <lower>-2.5</lower>
          <upper>2.5</upper>
          <effort>1000</effort>
          <velocity>0.5</velocity>
        </limit>
        <dynamics>
          <spring_reference>0</spring_reference>
          <spring_stiffness>0</spring_stiffness>
        </dynamics>
      </axis>
    </joint>
    <link name='arm_2'>
      <pose relative_to='arm_2_to_arm_1'>0 0 0 0 -0 0</pose>
      <inertial>
        <pose>0 0 0 0 -0 0</pose>
        <mass>1</mass>
        <inertia>
          <ixx>1</ixx>
          <ixy>0</ixy>
          <ixz>0</ixz>
          <iyy>1</iyy>
          <iyz>0</iyz>
          <izz>1</izz>
        </inertia>
      </inertial>
      <collision name='arm_2_collision'>
        <pose>0 0 0 0 -0 0</pose>
        <geometry>
          <box>
            <size>0.05 0.05 0.5</size>
          </box>
        </geometry>
      </collision>
      <visual name='arm_2_visual'>
        <pose>0.06 0 0.15 0 -0 0</pose>
        <geometry>
          <box>
            <size>0.05 0.05 0.5</size>
          </box>
        </geometry>
      </visual>
    </link>
    <joint name='left_gripper_joint' type='revolute'>
      <pose relative_to='arm_2'>0.06 0 0.4 0 -1.57 0</pose>
      <parent>arm_2</parent>
      <child>left_gripper</child>
      <axis>
        <xyz>0 0 1</xyz>
        <limit>
          <lower>0</lower>
          <upper>0.548</upper>
          <effort>1000</effort>
          <velocity>0.5</velocity>
        </limit>
        <dynamics>
          <spring_reference>0</spring_reference>
          <spring_stiffness>0</spring_stiffness>
        </dynamics>
      </axis>
    </joint>
    <link name='left_gripper'>
      <pose relative_to='left_gripper_joint'>0 0 0 0 -0 0</pose>
      <inertial>
        <pose>0 0 0 0 -0 0</pose>
        <mass>2</mass>
        <inertia>
          <ixx>2</ixx>
          <ixy>0</ixy>
          <ixz>0</ixz>
          <iyy>2</iyy>
          <iyz>0</iyz>
          <izz>2</izz>
        </inertia>
      </inertial>
      <collision name='left_gripper_collision'>
        <pose>0 0 0 0 -0 0</pose>
        <geometry>
          <box>
            <size>0.1 0.1 0.1</size>
          </box>
        </geometry>
      </collision>
      <collision name='left_gripper_fixed_joint_lump__left_tip_collision_1'>
        <pose>0 0 0 0 -0 0</pose>
        <geometry>
          <box>
            <size>0.1 0.1 0.1</size>
          </box>
        </geometry>
      </collision>
      <visual name='left_gripper_visual'>
        <pose>0 0 0 0 -0 0</pose>
        <geometry>
          <mesh>
            <scale>1 1 1</scale>
            <uri>model://pr2/meshes/gripper_v0/l_finger.dae</uri>
          </mesh>
        </geometry>
      </visual>
      <visual name='left_gripper_fixed_joint_lump__left_tip_visual_1'>
        <pose>0.09137 0.00495 0 0 -0 0</pose>
        <geometry>
          <mesh>
            <scale>1 1 1</scale>
            <uri>model://pr2/meshes/gripper_v0/l_finger_tip.dae</uri>
          </mesh>
        </geometry>
      </visual>
    </link>
    <joint name='right_gripper_joint' type='revolute'>
      <pose relative_to='arm_2'>0.06 0 0.4 0 -1.57 0</pose>
      <parent>arm_2</parent>
      <child>right_gripper</child>
      <axis>
        <xyz>0 0 -1</xyz>
        <limit>
          <lower>0</lower>
          <upper>0.548</upper>
          <effort>1000</effort>
          <velocity>0.5</velocity>
        </limit>
        <dynamics>
          <spring_reference>0</spring_reference>
          <spring_stiffness>0</spring_stiffness>
        </dynamics>
      </axis>
    </joint>
    <link name='right_gripper'>
      <pose relative_to='right_gripper_joint'>0 0 0 0 -0 0</pose>
      <inertial>
        <pose>0 0 0 0 -0 0</pose>
        <mass>2</mass>
        <inertia>
          <ixx>2</ixx>
          <ixy>0</ixy>
          <ixz>0</ixz>
          <iyy>2</iyy>
          <iyz>0</iyz>
          <izz>2</izz>
        </inertia>
      </inertial>
      <collision name='right_gripper_collision'>
        <pose>0 0 0 0 -0 0</pose>
        <geometry>
          <box>
            <size>0.1 0.1 0.1</size>
          </box>
        </geometry>
      </collision>
      <collision name='right_gripper_fixed_joint_lump__right_tip_collision_1'>
        <pose>0 0 0 0 -0 0</pose>
        <geometry>
          <box>
            <size>0.1 0.1 0.1</size>
          </box>
        </geometry>
      </collision>
      <visual name='right_gripper_visual'>
        <pose>0 0 0 -3.1415 0 0</pose>
        <geometry>
          <mesh>
            <scale>1 1 1</scale>
            <uri>model://pr2/meshes/gripper_v0/l_finger.dae</uri>
          </mesh>
        </geometry>
      </visual>
      <visual name='right_gripper_fixed_joint_lump__right_tip_visual_1'>
        <pose>0.09137 0.00495 0 -3.1415 0 0</pose>
        <geometry>
          <mesh>
            <scale>1 1 1</scale>
            <uri>model://pr2/meshes/gripper_v0/l_finger_tip.dae</uri>
          </mesh>
        </geometry>
      </visual>
    </link>
  </model>
</sdf>
